<robot name="panda">
<link name="world"/>
<link name="link_X"/>
<joint name="w_x" type="prismatic">
        <parent link="world"/>
        <child link="link_X" />
        <axis xyz="1 0 0" />
        <origin xyz="0 0 0" rpy="0 0 0"/>
        <safety_controller k_position="100.0" k_velocity="40.0" soft_lower_limit="-3.1416" soft_upper_limit="3.1416"/>
        <limit effort="870" lower="-1." upper="1." velocity="200."/>
</joint>

<link name="link_Y"/>
<joint name="x_y" type="prismatic">
        <parent link="link_X"/>
        <child link="link_Y" />
        <axis xyz="0 1 0" />
        <origin xyz="0 0 0" rpy="0 0 0"/>
        <safety_controller k_position="100.0" k_velocity="40.0" soft_lower_limit="-3.1416" soft_upper_limit="3.1416"/>
        <limit effort="870" lower="-1." upper="1." velocity="200."/>
</joint>

<link name="link_Z"/>
<joint name="y_z" type="prismatic">
        <parent link="link_Y"/>
        <child link="link_Z" />
        <axis xyz="0 0 1" />
        <origin xyz="0 0 0" rpy="0 0 0"/>
        <safety_controller k_position="100.0" k_velocity="40.0" soft_lower_limit="-3.1416" soft_upper_limit="3.1416"/>
        <limit effort="870" lower="-1." upper="1." velocity="200."/>
</joint>

<link name="link_y"/>
<joint name="z_y" type="revolute">
        <parent link="link_Z"/>
        <child link="link_y" />
        <axis xyz="0 0 1" />
        <origin xyz="0 0 0" rpy="0 0 0"/>
        <safety_controller k_position="100.0" k_velocity="40.0" soft_lower_limit="-3.1416" soft_upper_limit="3.1416"/>
        <limit effort="870" lower="-3.1416" upper="3.1416" velocity="314.16"/>
</joint>

<link name="link_p"/>
<joint name="y_p" type="revolute">
        <parent link="link_y"/>
        <child link="link_p" />
        <axis xyz="0 1 0" />
        <origin xyz="0 0 0" rpy="0 0 0"/>
        <safety_controller k_position="100.0" k_velocity="40.0" soft_lower_limit="-3.1416" soft_upper_limit="3.1416"/>
        <limit effort="870" lower="-3.1416" upper="3.1416" velocity="314.16"/>
</joint>

<link name="link_r"/>
<joint name="p_r" type="revolute">
        <parent link="link_p"/>
        <child link="link_r" />
        <axis xyz="1 0 0" />
        <origin xyz="0 0 0" rpy="0 0 0"/>
        <safety_controller k_position="100.0" k_velocity="40.0" soft_lower_limit="-3.1416" soft_upper_limit="3.1416"/>
        <limit effort="870" lower="-3.1416" upper="3.1416" velocity="314.16"/>
</joint>

<link name="panda_hand">
  	<inertial>
      <origin rpy="0 0 0" xyz="0 0 0"/>
       <mass value=".81"/>
       <inertia ixx="0.1" ixy="0" ixz="0" iyy="0.1" iyz="0" izz="0.1"/>
    </inertial>
    <visual>
      <geometry>
        <mesh filename="./meshes/visual/hand.obj"/>
      </geometry>
      <material name="panda_white"/>
    </visual>
    <collision>
      <geometry>
        <mesh filename="./meshes/collision/hand.obj"/>
      </geometry>
      <material name="panda_white"/>
    </collision>
</link>
<joint name="hand" type="fixed">
    <origin rpy="0 0 0" xyz="0 0 0"/>
    <parent link="link_r"/>
    <child link="panda_hand"/>
    <axis xyz="0 0 0"/>
</joint>

<link name="panda_leftfinger">
    <contact>
      <friction_anchor/>
      <stiffness value="30000.0"/>
      <damping value="1000.0"/>
      <spinning_friction value="0.1"/>
      <lateral_friction value="1.0"/>
    </contact>
  	<inertial>
      <origin rpy="0 0 0" xyz="0 0.01 0.02"/>
       <mass value="0.1"/>
       <inertia ixx="0.1" ixy="0" ixz="0" iyy="0.1" iyz="0" izz="0.1"/>
    </inertial>
    <visual>
      <geometry>
        <mesh filename="./meshes/visual/finger.obj"/>
      </geometry>
      <material name="panda_white"/>
    </visual>
    <collision>
      <geometry>
        <mesh filename="./meshes/collision/finger.obj"/>
      </geometry>
      <material name="panda_white"/>
    </collision>
</link>
<joint name="hand_finger_left" type="prismatic">
    <origin rpy="0 0 0" xyz="0 0 0.0584"/>
    <parent link="panda_hand" />
    <child link="panda_leftfinger" />
    <axis xyz="0 1 0"/>
    <limit effort="80" lower="0.0" upper="0.04" velocity="1."/>
</joint>

<link name="panda_rightfinger">
    <contact>
      <friction_anchor/>
      <stiffness value="30000.0"/>
      <damping value="1000.0"/>
      <spinning_friction value="0.1"/>
      <lateral_friction value="1.0"/>
    </contact>

  	<inertial>
      <origin rpy="0 0 0" xyz="0 -0.01 0.02"/>
       <mass value="0.1"/>
       <inertia ixx="0.1" ixy="0" ixz="0" iyy="0.1" iyz="0" izz="0.1"/>
    </inertial>
    <visual>
      <origin rpy="0 0 3.14159265359" xyz="0 0 0"/>
      <geometry>
        <mesh filename="./meshes/visual/finger.obj"/>
      </geometry>
      <material name="panda_white"/>
    </visual>
    <collision>
      <origin rpy="0 0 3.14159265359" xyz="0 0 0"/>
      <geometry>
        <mesh filename="./meshes/collision/finger.obj"/>
      </geometry>
      <material name="panda_white"/>
    </collision>
</link>
<joint name="hand_finger_right" type="prismatic">
    <origin rpy="0 0 0" xyz="0 0 0.0584"/>
    <parent link="panda_hand" />
    <child link="panda_rightfinger" />
    <axis xyz="0 -1 0"/>
    <limit effort="80" lower="0.0" upper="0.04" velocity="1."/>
    <mimic joint="hand_finger_left" />
</joint>
</robot>